2022-03-19 22:59:15,356 - ERROR - Traceback (most recent call last):
  File "C:\Users\yoshy\.virtualenvs\FerrisBot-KMNWXFqb\lib\site-packages\discord\ext\commands\core.py", line 85, in wrapped
    ret = await coro(*args, **kwargs)
  File "C:\Users\yoshy\OneDrive\Dokumente\Coding\Recreational\FerrisBot\bot.py", line 64, in extension
    embed = util.standard_embed(ctx, 'Shows loaded extensions', title='Loaded Extensions')
  File "C:\Users\yoshy\OneDrive\Dokumente\Coding\Recreational\FerrisBot\util.py", line 16, in standard_embed
    embed.set_footer(text=f'Command Invoked by {str(ctx.author)}', icon_url=ctx.author.avatar.url)
AttributeError: 'str' object has no attribute 'url'

The above exception was the direct cause of the following exception:

Traceback (most recent call last):
  File "C:\Users\yoshy\.virtualenvs\FerrisBot-KMNWXFqb\lib\site-packages\discord\ext\commands\bot.py", line 939, in invoke
    await ctx.command.invoke(ctx)
  File "C:\Users\yoshy\.virtualenvs\FerrisBot-KMNWXFqb\lib\site-packages\discord\ext\commands\core.py", line 1342, in invoke
    await injected(*ctx.args, **ctx.kwargs)
  File "C:\Users\yoshy\.virtualenvs\FerrisBot-KMNWXFqb\lib\site-packages\discord\ext\commands\core.py", line 94, in wrapped
    raise CommandInvokeError(exc) from exc
discord.ext.commands.errors.CommandInvokeError: Command raised an exception: AttributeError: 'str' object has no attribute 'url'

2022-03-19 22:59:15,356 - ERROR - Traceback (most recent call last):
  File "C:\Users\yoshy\.virtualenvs\FerrisBot-KMNWXFqb\lib\site-packages\discord\ext\commands\core.py", line 85, in wrapped
    ret = await coro(*args, **kwargs)
  File "C:\Users\yoshy\OneDrive\Dokumente\Coding\Recreational\FerrisBot\bot.py", line 64, in extension
    embed = util.standard_embed(ctx, 'Shows loaded extensions', title='Loaded Extensions')
  File "C:\Users\yoshy\OneDrive\Dokumente\Coding\Recreational\FerrisBot\util.py", line 16, in standard_embed
    embed.set_footer(text=f'Command Invoked by {str(ctx.author)}', icon_url=ctx.author.avatar.url)
AttributeError: 'str' object has no attribute 'url'

The above exception was the direct cause of the following exception:

Traceback (most recent call last):
  File "C:\Users\yoshy\.virtualenvs\FerrisBot-KMNWXFqb\lib\site-packages\discord\ext\commands\bot.py", line 939, in invoke
    await ctx.command.invoke(ctx)
  File "C:\Users\yoshy\.virtualenvs\FerrisBot-KMNWXFqb\lib\site-packages\discord\ext\commands\core.py", line 1342, in invoke
    await injected(*ctx.args, **ctx.kwargs)
  File "C:\Users\yoshy\.virtualenvs\FerrisBot-KMNWXFqb\lib\site-packages\discord\ext\commands\core.py", line 94, in wrapped
    raise CommandInvokeError(exc) from exc
discord.ext.commands.errors.CommandInvokeError: Command raised an exception: AttributeError: 'str' object has no attribute 'url'

2022-03-19 23:01:43,030 - ERROR - discord.ext.commands.errors.CommandNotFound: Command "help" is not found

2022-03-19 23:06:18,236 - ERROR - discord.ext.commands.errors.CommandNotFound: Command "extensions" is not found

2022-03-19 23:06:35,674 - ERROR - Traceback (most recent call last):
  File "C:\Users\yoshy\.virtualenvs\FerrisBot-KMNWXFqb\lib\site-packages\discord\ext\commands\core.py", line 85, in wrapped
    ret = await coro(*args, **kwargs)
  File "C:\Users\yoshy\OneDrive\Dokumente\Coding\Recreational\FerrisBot\bot.py", line 93, in unload_extension
    await util.send_embed(ctx, util.standard_embed(ctx, f'Extension ``{name}`` unloaded.'), color=discord.Color.green())
TypeError: send_embed() got an unexpected keyword argument 'color'

The above exception was the direct cause of the following exception:

Traceback (most recent call last):
  File "C:\Users\yoshy\.virtualenvs\FerrisBot-KMNWXFqb\lib\site-packages\discord\ext\commands\bot.py", line 939, in invoke
    await ctx.command.invoke(ctx)
  File "C:\Users\yoshy\.virtualenvs\FerrisBot-KMNWXFqb\lib\site-packages\discord\ext\commands\core.py", line 1348, in invoke
    await ctx.invoked_subcommand.invoke(ctx)
  File "C:\Users\yoshy\.virtualenvs\FerrisBot-KMNWXFqb\lib\site-packages\discord\ext\commands\core.py", line 863, in invoke
    await injected(*ctx.args, **ctx.kwargs)
  File "C:\Users\yoshy\.virtualenvs\FerrisBot-KMNWXFqb\lib\site-packages\discord\ext\commands\core.py", line 94, in wrapped
    raise CommandInvokeError(exc) from exc
discord.ext.commands.errors.CommandInvokeError: Command raised an exception: TypeError: send_embed() got an unexpected keyword argument 'color'

2022-03-19 23:06:35,674 - ERROR - Traceback (most recent call last):
  File "C:\Users\yoshy\.virtualenvs\FerrisBot-KMNWXFqb\lib\site-packages\discord\ext\commands\core.py", line 85, in wrapped
    ret = await coro(*args, **kwargs)
  File "C:\Users\yoshy\OneDrive\Dokumente\Coding\Recreational\FerrisBot\bot.py", line 93, in unload_extension
    await util.send_embed(ctx, util.standard_embed(ctx, f'Extension ``{name}`` unloaded.'), color=discord.Color.green())
TypeError: send_embed() got an unexpected keyword argument 'color'

The above exception was the direct cause of the following exception:

Traceback (most recent call last):
  File "C:\Users\yoshy\.virtualenvs\FerrisBot-KMNWXFqb\lib\site-packages\discord\ext\commands\bot.py", line 939, in invoke
    await ctx.command.invoke(ctx)
  File "C:\Users\yoshy\.virtualenvs\FerrisBot-KMNWXFqb\lib\site-packages\discord\ext\commands\core.py", line 1348, in invoke
    await ctx.invoked_subcommand.invoke(ctx)
  File "C:\Users\yoshy\.virtualenvs\FerrisBot-KMNWXFqb\lib\site-packages\discord\ext\commands\core.py", line 863, in invoke
    await injected(*ctx.args, **ctx.kwargs)
  File "C:\Users\yoshy\.virtualenvs\FerrisBot-KMNWXFqb\lib\site-packages\discord\ext\commands\core.py", line 94, in wrapped
    raise CommandInvokeError(exc) from exc
discord.ext.commands.errors.CommandInvokeError: Command raised an exception: TypeError: send_embed() got an unexpected keyword argument 'color'

2022-03-19 23:07:57,344 - ERROR - discord.ext.commands.errors.CommandNotFound: Command "command" is not found

2022-03-19 23:07:59,480 - ERROR - discord.ext.commands.errors.CommandNotFound: Command "help" is not found

2022-03-19 23:08:03,422 - ERROR - Traceback (most recent call last):
  File "C:\Users\yoshy\.virtualenvs\FerrisBot-KMNWXFqb\lib\site-packages\discord\ext\commands\bot.py", line 939, in invoke
    await ctx.command.invoke(ctx)
  File "C:\Users\yoshy\.virtualenvs\FerrisBot-KMNWXFqb\lib\site-packages\discord\ext\commands\core.py", line 1329, in invoke
    await self.prepare(ctx)
  File "C:\Users\yoshy\.virtualenvs\FerrisBot-KMNWXFqb\lib\site-packages\discord\ext\commands\core.py", line 778, in prepare
    raise CheckFailure('The check functions for command {0.qualified_name} failed.'.format(self))
discord.ext.commands.errors.CheckFailure: The check functions for command extension failed.

